<!-- 添加机器人并添加摄像头 -->
<robot name="mycar">
    <!-- 底盘link -->
    <link name="base_link">
        <visual>
            <geometry>
                <box size="0.3 0.2 0.1" />
            </geometry>
            <origin xyz="0 0 0" rpy="0 0 0" />
            <material name="car_color">
                <color rgba="0.8 0.5 0 0.5" />
            </material>
        </visual>
    </link>

    <!-- 摄像头 -->
    <link name="camera">
        <visual>
            <geometry>
                <box size="0.02 0.05 0.05" />
            </geometry>
            <!-- 后期需要修改origin中xyz参数 -->
            <origin xyz="0 0 0.025" rpy="0 0 0" />
            <material name="camera_color">
                <color rgba="0 0 1 0.5" />
            </material>
        </visual>
    </link>

    <!-- 关节 -->
    <joint name="camera2base" type="continuous">
        <!-- 父级link -->
        <parent link="base_link" />
        <!-- 子级link -->
        <child link="camera" />
        <!-- 设置偏移量 -->
        <!-- 注意！如果这里不是全接触，会发生抖动 -->
        <origin xyz="0.1 0 0.05" rpy="0 0 0" />
        <!-- 设置关节旋转参考周 -->
        <axis xyz="0 0 1" />
    </joint>

</robot>