<!-- 添加机器人并添加摄像头 -->
<robot name="turtlebot">
    <!-- base_footprint -->
    <link name="base_footprint">
        <visual>
            <geometry>
                <sphere radius="0.001" />
            </geometry>
        </visual>
    </link>
    <!-- 底盘 -->
    <link name="base_link">
        <visual>
            <geometry>
                <cylinder radius="0.1" length="0.08" />
            </geometry>
            <origin xyz="0 0 0.015" rpy="0 0 0" />
            <material name="chassis_color">
                <color rgba="0.8 0.5 0 0.5" />
            </material>
        </visual>
    </link>
    <!-- 关节 -->
    <joint name="footprint2baselink" type="fixed">
        <!-- 父级link -->
        <parent link="base_footprint" />
        <!-- 子级link -->
        <child link="base_link" />
        <!-- 设置两个坐标轴的偏移量 -->
        <origin xyz="0 0 0.055" rpy="0 0 0" />
    </joint>

    <!-- 左驱动轮 -->
    <link name="wheel_left">
        <visual>
            <geometry>
                <cylinder radius="0.0325" length="0.015" />
            </geometry>
            <origin xyz="0 0 0" rpy="1.5705 0 0" />
            <material name="black">
                <color rgba="0.0 0.0 0.0 1.0" />
            </material>
        </visual>
    </link>
    <!-- 关节 -->
    <joint name="baselink2wheel_left" type="continuous">
        <!-- 父级link -->
        <parent link="base_link" />
        <!-- 子级link -->
        <child link="wheel_left" />
        <!-- 设置两个坐标轴的偏移量 -->
        <origin xyz="0 0.1 -0.0225" rpy="0 0 0" />
        <axis xyz="0 1 0" />
    </joint>

    <!-- 右驱动轮 -->
    <link name="wheel_right">
        <visual>
            <geometry>
                <cylinder radius="0.0325" length="0.015" />
            </geometry>
            <origin xyz="0 0 0" rpy="1.5705 0 0" />
            <material name="black">
                <color rgba="0.0 0.0 0.0 1.0" />
            </material>
        </visual>
    </link>
    <!-- 关节 -->
    <joint name="baselink2wheel_right" type="continuous">
        <!-- 父级link -->
        <parent link="base_link" />
        <!-- 子级link -->
        <child link="wheel_right" />
        <!-- 设置两个坐标轴的偏移量 -->
        <origin xyz="0 -0.1 -0.0225" rpy="0 0 0" />
        <axis xyz="0 1 0" />
    </joint>

    <link name="front_wheel">
        <visual>
            <geometry>
                <sphere radius="0.0075" />
            </geometry>
            <origin xyz="0 0 0" rpy="0 0 0" />
            <material name="black">
                <color rgba="0.0 0.0 0.0 1.0" />
            </material>
        </visual>
    </link>

    <joint name="front_wheel2base_link" type="continuous">
        <parent link="base_link" />
        <child link="front_wheel" />
        <origin xyz="0.0925 0 -0.0475" />
        <axis xyz="1 1 1" />
    </joint>

    <link name="back_wheel">
        <visual>
            <geometry>
                <sphere radius="0.0075" />
            </geometry>
            <origin xyz="0 0 0" rpy="0 0 0" />
            <material name="black">
                <color rgba="0.0 0.0 0.0 1.0" />
            </material>
        </visual>
    </link>

    <joint name="back_wheel2base_link" type="continuous">
        <parent link="base_link" />
        <child link="back_wheel" />
        <origin xyz="-0.0925 0 -0.0475" />
        <axis xyz="1 1 1" />
    </joint>



</robot>